<?xml version="1.0" ?>
<!-- =================================================================================== -->
<!-- |    This document was autogenerated by xacro from v10.urdf.xacro                 | -->
<!-- |    EDITING THIS FILE BY HAND IS NOT RECOMMENDED                                 | -->
<!-- =================================================================================== -->
<robot name="openarm">
  <!--
    DEPRECATION NOTICE
    argument arm_type is no longer supported and will be removed in the future.
    This argument is ignored.
  -->
  <!-- Should the robot be spawned in Gazebo with effort interfaces?" -->
  <!-- <xacro:arg name="gazebo_effort" default="false" /> -->
  <!-- ========================================================== -->
  <!-- Adds the required tags to simulate one joint in gazebo     -->
  <!--                                                            -->
  <!-- joint - Name of the openarm joint to simulate                  -->
  <!-- transmission - type of the transmission of the joint       -->
  <!-- ========================================================== -->
  <!-- <xacro:macro name="gazebo-joint" params="joint transmission:=hardware_interface/EffortJointInterface">
    <gazebo reference="${joint}">
      <provideFeedback>true</provideFeedback>
    </gazebo>
    <transmission name="${joint}_transmission">
      <type>transmission_interface/SimpleTransmission</type>
      <joint name="${joint}">
        <hardwareInterface>${transmission}</hardwareInterface>
      </joint>
      <actuator name="${joint}_motor">
        <hardwareInterface>${transmission}</hardwareInterface>
      </actuator>
    </transmission>
  </xacro:macro> -->
  <!-- <xacro:macro name="gazebo-friction" params="link mu">
    <gazebo reference="${link}">
      <collision>
        <max_contacts>10</max_contacts>
        <surface>
          <contact>
            <ode>
              <max_vel>0</max_vel>
              <min_depth>0.001</min_depth>
            </ode>
          </contact>
          <friction>
            <ode>
              <mu>${mu}</mu>
              <mu2>${mu}</mu2>
            </ode>
          </friction>
          <bounce/>
        </surface>
      </collision>
    </gazebo>
  </xacro:macro> -->
  <!-- ========================================================== -->
  <!-- Adds the required tags to simulate one joint in gazebo     -->
  <!--                                                            -->
  <!-- joint - Name of the openarm joint to simulate                  -->
  <!-- transmission - type of the transmission of the joint       -->
  <!-- ========================================================== -->
  <!-- <xacro:macro name="gazebo-joint" params="joint transmission:=hardware_interface/EffortJointInterface">
    <gazebo reference="${joint}">
      <provideFeedback>true</provideFeedback>
    </gazebo>
    <transmission name="${joint}_transmission">
      <type>transmission_interface/SimpleTransmission</type>
      <joint name="${joint}">
        <hardwareInterface>${transmission}</hardwareInterface>
      </joint>
      <actuator name="${joint}_motor">
        <hardwareInterface>${transmission}</hardwareInterface>
      </actuator>
    </transmission>
  </xacro:macro> -->
  <!-- <xacro:macro name="gazebo-friction" params="link mu">
    <gazebo reference="${link}">
      <collision>
        <max_contacts>10</max_contacts>
        <surface>
          <contact>
            <ode>
              <max_vel>0</max_vel>
              <min_depth>0.001</min_depth>
            </ode>
          </contact>
          <friction>
            <ode>
              <mu>${mu}</mu>
              <mu2>${mu}</mu2>
            </ode>
          </friction>
          <bounce/>
        </surface>
      </collision>
    </gazebo>
  </xacro:macro> -->
  <!-- arm_type: Namespace of the robot arm. Serves to differentiate between arms in case of multiple instances. -->
  <!-- joint_limits: description of the joint limits that comes from a YAML file. Example definition: ${xacro.load_yaml('$(find openarm_description)/robots/fr3/joint_limits.yaml')} -->
  <!-- kinematics: description of the kinematics that comes from a YAML file. Example definition: ${xacro.load_yaml('$(find openarm_description)/robots/fr3/kinematics.yaml')} -->
  <!-- inertials: description of the inertials that comes from a YAML file. Example definition: ${xacro.load_yaml('$(find openarm_description)/robots/fr3/inertials.yaml')} -->
  <!-- Is the robot being simulated in gazebo? -->
  <!-- <xacro:arg name="gazebo" default="false" /> -->
  <material name="light_gray">
    <color rgba="0.4 0.4 0.4 1.0"/>
  </material>
  <material name="gray">
    <color rgba="0.2117647058823529 0.2117647058823529 0.2117647058823529 1.0"/>
  </material>
  <material name="dark_gray">
    <color rgba="0.1607843137254902 0.1607843137254902 0.1607843137254902 1.0"/>
  </material>
  <material name="light_black">
    <color rgba="0.08 0.08 0.08 1.0"/>
  </material>
  <material name="black">
    <color rgba="0.0 0.0 0.0 1.0"/>
  </material>
  <link name="world"/>
  <joint name="openarm_body_world_joint" type="fixed">
    <parent link="world"/>
    <child link="openarm_body_link0"/>
    <origin rpy="0 0 -2.36" xyz="0 0 0"/>
  </joint>
  <link name="openarm_body_link0">
    <visual name="openarm_body_link0_visual">
      <origin rpy="0.0 0.0 0.0" xyz="0.0 0.0 0.0"/>
      <geometry>
        <mesh filename="./meshes/body/v10/visual/body_link0.stl" scale="0.001 0.001 0.001"/>
      </geometry>
      <material name="light_black"/>
    </visual>
    <collision name="openarm_body_link0_collision">
      <origin rpy="0.0 0.0 0.0" xyz="0.0 0.0 0.0"/>
      <geometry>
      </geometry>
    </collision>
    <inertial>
      <origin rpy="0.0 0.0 0.0" xyz="0.0 0.0 0.0"/>
      <mass value="13.89"/>
      <inertia ixx="1.653" ixy="0.0" ixz="0.0" iyy="1.653" iyz="0.0" izz="0.051"/>
    </inertial>
  </link>
  <!-- Define a property that defaults to 'arm_prefix_arm_type' concatenated with an underscore if 'no_prefix' is not set -->
  <!-- <xacro:if value="${gazebo}">
      <xacro:property name="connected_to" value="" />
    </xacro:if> -->
  <!-- <link name="${connected_to}">
      </link> -->
  <joint name="openarm_left_openarm_body_link0_joint" type="fixed">
    <parent link="openarm_body_link0"/>
    <child link="openarm_left_link0"/>
    <origin rpy="-1.5708 0 0" xyz="0.0 0.031 0.698"/>
  </joint>
  <link name="openarm_left_link0">
    <visual name="openarm_left_link0_visual">
      <origin rpy="0.0 0.0 0.0" xyz="0.0 0.0 0.0"/>
      <geometry>
        <mesh filename="./meshes/arm/v10/visual/link0.stl" scale="0.001 -0.001 0.001"/>
      </geometry>
      <material name="light_black"/>
    </visual>
    <collision name="openarm_left_link0_collision">
      <origin rpy="0.0 0.0 0.0" xyz="0.0 0.0 0.0"/>
      <geometry>
        

      </geometry>
    </collision>
    <inertial>
      <origin rpy="0.0 0.0 0.0" xyz="-0.0009483362816297526 0.0001580207020448382 0.03076860287587199"/>
      <mass value="1.1432284943239561"/>
      <inertia ixx="0.001128" ixy="-4e-06" ixz="-3.3e-05" iyy="0.000962" iyz="-7e-06" izz="0.00147"/>
    </inertial>
  </link>
  <link name="openarm_left_link1">
    <visual name="openarm_left_link1_visual">
      <origin rpy="0.0 0.0 0.0" xyz="-0.0 0.0 -0.0625"/>
      <geometry>
        <mesh filename="./meshes/arm/v10/visual/link1.stl" scale="0.001 -0.001 0.001"/>
      </geometry>
      <material name="light_black"/>
    </visual>
    <collision name="openarm_left_link1_collision">
      <origin rpy="0.0 0.0 0.0" xyz="-0.0 0.0 -0.0625"/>
      <geometry>
        
        
      </geometry>
    </collision>
    <inertial>
      <origin rpy="0.0 0.0 0.0" xyz="0.0011467657911800769 3.319987657026362e-05 0.05395284380736254"/>
      <mass value="1.1416684646202298"/>
      <inertia ixx="0.001567" ixy="-1e-06" ixz="-2.9e-05" iyy="0.001273" iyz="-0.0" izz="0.001016"/>
    </inertial>
  </link>
  <joint name="L_J1" type="revolute">
    <origin rpy="0 0 0" xyz="0.0 0.0 0.0625"/>
    <parent link="openarm_left_link0"/>
    <child link="openarm_left_link1"/>
    <axis xyz="0 0 1"/>
    <limit effort="54" lower="-3.490659" upper="1.3962629999999998" velocity="45"/>
  </joint>
  <link name="openarm_left_link2">
    <visual name="openarm_left_link2_visual">
      <origin rpy="0.0 0.0 0.0" xyz="0.0301 0.0 -0.1225"/>
      <geometry>
        <mesh filename="./meshes/arm/v10/visual/link2.stl" scale="0.001 -0.001 0.001"/>
      </geometry>
      <material name="light_black"/>
    </visual>
    <collision name="openarm_left_link2_collision">
      <origin rpy="0.0 0.0 0.0" xyz="0.0301 0.0 -0.1225"/>
      <geometry>
        
        
      </geometry>
    </collision>
    <inertial>
      <origin rpy="0.0 0.0 0.0" xyz="0.00839629182351943 -2.0145102027597523e-08 0.03256649300522363"/>
      <mass value="0.2775092746011571"/>
      <inertia ixx="0.000359" ixy="-0.0" ixz="-0.000109" iyy="0.000376" iyz="0.0" izz="0.000232"/>
    </inertial>
  </link>
  <joint name="L_J2" type="revolute">
    <origin rpy="-1.57079632679 0 0" xyz="-0.0301 0.0 0.06"/>
    <parent link="openarm_left_link1"/>
    <child link="openarm_left_link2"/>
    <axis xyz="-1 0 0"/>
    <limit effort="54" lower="-3.3161253267948965" upper="0.17453267320510335" velocity="45"/>
  </joint>
  <link name="openarm_left_link3">
    <visual name="openarm_left_link3_visual">
      <origin rpy="0.0 0.0 0.0" xyz="-0.0 -0.0 -0.18875"/>
      <geometry>
        <mesh filename="./meshes/arm/v10/visual/link3.stl" scale="0.001 -0.001 0.001"/>
      </geometry>
      <material name="dark_gray"/>
    </visual>
    <collision name="openarm_left_link3_collision">
      <origin rpy="0.0 0.0 0.0" xyz="-0.0 -0.0 -0.18875"/>
      <geometry>
        
        
      </geometry>
    </collision>
    <inertial>
      <origin rpy="0.0 0.0 0.0" xyz="-0.002104752099628911 0.0005549085042607548 0.08847470545721961"/>
      <mass value="1.073863338202347"/>
      <inertia ixx="0.004372" ixy="-0.0" ixz="1.1e-05" iyy="0.004319" iyz="-3.6e-05" izz="0.000661"/>
    </inertial>
  </link>
  <joint name="L_J3" type="revolute">
    <origin rpy="0 0 0" xyz="0.0301 0.0 0.06625"/>
    <parent link="openarm_left_link2"/>
    <child link="openarm_left_link3"/>
    <axis xyz="0 0 1"/>
    <limit effort="28" lower="-1.570796" upper="1.570796" velocity="8"/>
  </joint>
  <link name="openarm_left_link4">
    <visual name="openarm_left_link4_visual">
      <origin rpy="0.0 0.0 0.0" xyz="0.0 -0.0315 -0.3425"/>
      <geometry>
        <mesh filename="./meshes/arm/v10/visual/link4.stl" scale="0.001 0.001 0.001"/>
      </geometry>
      <material name="gray"/>
    </visual>
    <collision name="openarm_left_link4_collision">
      <origin rpy="0.0 0.0 0.0" xyz="0.0 -0.0315 -0.3425"/>
      <geometry>
        
        
      </geometry>
    </collision>
    <inertial>
      <origin rpy="0.0 0.0 0.0" xyz="-0.0029006831074562967 -0.03030575826634669 0.06339637422196209"/>
      <mass value="1.3699337287025453"/>
      <inertia ixx="0.001577" ixy="-5e-06" ixz="-7.5e-05" iyy="0.001346" iyz="0.000108" izz="0.001104"/>
    </inertial>
  </link>
  <joint name="L_J4" type="revolute">
    <origin rpy="0 0 0" xyz="-0.0 0.0315 0.15375"/>
    <parent link="openarm_left_link3"/>
    <child link="openarm_left_link4"/>
    <axis xyz="0 1 0"/>
    <limit effort="28" lower="0.0" upper="2.443461" velocity="8"/>
  </joint>
  <link name="openarm_left_link5">
    <visual name="openarm_left_link5_visual">
      <origin rpy="0.0 0.0 0.0" xyz="-0.0 -0.0 -0.438"/>
      <geometry>
        <mesh filename="./meshes/arm/v10/visual/link5.stl" scale="0.001 -0.001 0.001"/>
      </geometry>
      <material name="dark_gray"/>
    </visual>
    <collision name="openarm_left_link5_collision">
      <origin rpy="0.0 0.0 0.0" xyz="-0.0 -0.0 -0.438"/>
      <geometry>
        
        
      </geometry>
    </collision>
    <inertial>
      <origin rpy="0.0 0.0 0.0" xyz="-0.003049665024221911 0.0008866902457326625 0.043079803024980934"/>
      <mass value="0.5506588026168502"/>
      <inertia ixx="0.000423" ixy="-8e-06" ixz="6e-06" iyy="0.000445" iyz="-6e-06" izz="0.000324"/>
    </inertial>
  </link>
  <joint name="L_J5" type="revolute">
    <origin rpy="0 0 0" xyz="0.0 -0.0315 0.0955"/>
    <parent link="openarm_left_link4"/>
    <child link="openarm_left_link5"/>
    <axis xyz="0 0 1"/>
    <limit effort="10" lower="-1.570796" upper="1.570796" velocity="30"/>
  </joint>
  <link name="openarm_left_link6">
    <visual name="openarm_left_link6_visual">
      <origin rpy="0.0 0.0 0.0" xyz="-0.0375 -0.0 -0.5585"/>
      <geometry>
        <mesh filename="./meshes/arm/v10/visual/link6.stl" scale="0.001 -0.001 0.001"/>
      </geometry>
      <material name="light_black"/>
    </visual>
    <collision name="openarm_left_link6_collision">
      <origin rpy="0.0 0.0 0.0" xyz="-0.0375 -0.0 -0.5585"/>
      <geometry>
        
        
      </geometry>
    </collision>
    <inertial>
      <origin rpy="0.0 0.0 0.0" xyz="-0.037136587005447405 0.00033230528343419053 -9.498374522309838e-05"/>
      <mass value="0.3540202773187987"/>
      <inertia ixx="0.000143" ixy="4e-06" ixz="0.0" iyy="0.000157" iyz="1e-06" izz="0.000159"/>
    </inertial>
  </link>
  <joint name="L_J6" type="revolute">
    <origin rpy="0 0 0" xyz="0.0375 0.0 0.1205"/>
    <parent link="openarm_left_link5"/>
    <child link="openarm_left_link6"/>
    <axis xyz="1 0 0"/>
    <limit effort="10" lower="-0.785398" upper="0.785398" velocity="30"/>
  </joint>
  <link name="openarm_left_link7">
    <visual name="openarm_left_link7_visual">
      <origin rpy="0.0 0.0 0.0" xyz="0.0 -0.0 -0.5585"/>
      <geometry>
        <mesh filename="./meshes/arm/v10/visual/link7.stl" scale="0.001 -0.001 0.001"/>
      </geometry>
      <material name="gray"/>
    </visual>
    <collision name="openarm_left_link7_collision">
      <origin rpy="0.0 0.0 0.0" xyz="0.0 -0.0 -0.5585"/>
      <geometry>
        
        
      </geometry>
    </collision>
    <inertial>
      <origin rpy="0.0 0.0 0.0" xyz="6.875510271106056e-05 -0.01766175250761268 0.06651945409987448"/>
      <mass value="0.5499771327380578"/>
      <inertia ixx="0.000639" ixy="0.0" ixz="-0.0" iyy="0.000497" iyz="8.9e-05" izz="0.000342"/>
    </inertial>
  </link>
  <joint name="L_J7" type="revolute">
    <origin rpy="0 0 0" xyz="-0.0375 0.0 0.0"/>
    <parent link="openarm_left_link6"/>
    <child link="openarm_left_link7"/>
    <axis xyz="0 -1 0"/>
    <limit effort="10" lower="-1.570796" upper="1.570796" velocity="30"/>
  </joint>
  <link name="openarm_left_link8"/>
  <joint name="L_J8" type="fixed">
    <origin rpy="0 0 0" xyz="1e-06 0.0205 0.0"/>
    <parent link="openarm_left_link7"/>
    <child link="openarm_left_link8"/>
  </joint>
  <!-- Define a property that defaults to 'arm_prefix_arm_type' concatenated with an underscore if 'no_prefix' is not set -->
  <!-- <xacro:if value="${gazebo}">
      <xacro:property name="connected_to" value="" />
    </xacro:if> -->
  <!-- <link name="${connected_to}">
      </link> -->
  <joint name="openarm_right_openarm_body_link0_joint" type="fixed">
    <parent link="openarm_body_link0"/>
    <child link="openarm_right_link0"/>
    <origin rpy="1.5708 0 0" xyz="0.0 -0.031 0.698"/>
  </joint>
  <link name="openarm_right_link0">
    <visual name="openarm_right_link0_visual">
      <origin rpy="0.0 0.0 0.0" xyz="0.0 0.0 0.0"/>
      <geometry>
        <mesh filename="./meshes/arm/v10/visual/link0.stl" scale="0.001 0.001 0.001"/>
      </geometry>
      <material name="light_black"/>
    </visual>
    <collision name="openarm_right_link0_collision">
      <origin rpy="0.0 0.0 0.0" xyz="0.0 0.0 0.0"/>
      <geometry>
        
        
      </geometry>
    </collision>
    <inertial>
      <origin rpy="0.0 0.0 0.0" xyz="-0.0009483362816297526 0.0001580207020448382 0.03076860287587199"/>
      <mass value="1.1432284943239561"/>
      <inertia ixx="0.001128" ixy="-4e-06" ixz="-3.3e-05" iyy="0.000962" iyz="-7e-06" izz="0.00147"/>
    </inertial>
  </link>
  <link name="openarm_right_link1">
    <visual name="openarm_right_link1_visual">
      <origin rpy="0.0 0.0 0.0" xyz="-0.0 0.0 -0.0625"/>
      <geometry>
        <mesh filename="./meshes/arm/v10/visual/link1.stl" scale="0.001 0.001 0.001"/>
      </geometry>
      <material name="light_black"/>
    </visual>
    <collision name="openarm_right_link1_collision">
      <origin rpy="0.0 0.0 0.0" xyz="-0.0 0.0 -0.0625"/>
      <geometry>
        
        
      </geometry>
    </collision>
    <inertial>
      <origin rpy="0.0 0.0 0.0" xyz="0.0011467657911800769 3.319987657026362e-05 0.05395284380736254"/>
      <mass value="1.1416684646202298"/>
      <inertia ixx="0.001567" ixy="-1e-06" ixz="-2.9e-05" iyy="0.001273" iyz="-0.0" izz="0.001016"/>
    </inertial>
  </link>
  <joint name="R_J1" type="revolute">
    <origin rpy="0 0 0" xyz="0.0 0.0 0.0625"/>
    <parent link="openarm_right_link0"/>
    <child link="openarm_right_link1"/>
    <axis xyz="0 0 1"/>
    <limit effort="54" lower="-1.396263" upper="3.490659" velocity="45"/>
  </joint>
  <link name="openarm_right_link2">
    <visual name="openarm_right_link2_visual">
      <origin rpy="0.0 0.0 0.0" xyz="0.0301 0.0 -0.1225"/>
      <geometry>
        <mesh filename="./meshes/arm/v10/visual/link2.stl" scale="0.001 0.001 0.001"/>
      </geometry>
      <material name="light_black"/>
    </visual>
    <collision name="openarm_right_link2_collision">
      <origin rpy="0.0 0.0 0.0" xyz="0.0301 0.0 -0.1225"/>
      <geometry>
        
        
      </geometry>
    </collision>
    <inertial>
      <origin rpy="0.0 0.0 0.0" xyz="0.00839629182351943 -2.0145102027597523e-08 0.03256649300522363"/>
      <mass value="0.2775092746011571"/>
      <inertia ixx="0.000359" ixy="-0.0" ixz="-0.000109" iyy="0.000376" iyz="0.0" izz="0.000232"/>
    </inertial>
  </link>
  <joint name="R_J2" type="revolute">
    <origin rpy="1.57079632679 0 0" xyz="-0.0301 0.0 0.06"/>
    <parent link="openarm_right_link1"/>
    <child link="openarm_right_link2"/>
    <axis xyz="-1 0 0"/>
    <limit effort="54" lower="-0.17453267320510335" upper="3.3161253267948965" velocity="45"/>
  </joint>
  <link name="openarm_right_link3">
    <visual name="openarm_right_link3_visual">
      <origin rpy="0.0 0.0 0.0" xyz="-0.0 -0.0 -0.18875"/>
      <geometry>
        <mesh filename="./meshes/arm/v10/visual/link3.stl" scale="0.001 0.001 0.001"/>
      </geometry>
      <material name="dark_gray"/>
    </visual>
    <collision name="openarm_right_link3_collision">
      <origin rpy="0.0 0.0 0.0" xyz="-0.0 -0.0 -0.18875"/>
      <geometry>
        
        
      </geometry>
    </collision>
    <inertial>
      <origin rpy="0.0 0.0 0.0" xyz="-0.002104752099628911 0.0005549085042607548 0.08847470545721961"/>
      <mass value="1.073863338202347"/>
      <inertia ixx="0.004372" ixy="-0.0" ixz="1.1e-05" iyy="0.004319" iyz="-3.6e-05" izz="0.000661"/>
    </inertial>
  </link>
  <joint name="R_J3" type="revolute">
    <origin rpy="0 0 0" xyz="0.0301 0.0 0.06625"/>
    <parent link="openarm_right_link2"/>
    <child link="openarm_right_link3"/>
    <axis xyz="0 0 1"/>
    <limit effort="28" lower="-1.570796" upper="1.570796" velocity="8"/>
  </joint>
  <link name="openarm_right_link4">
    <visual name="openarm_right_link4_visual">
      <origin rpy="0.0 0.0 0.0" xyz="0.0 -0.0315 -0.3425"/>
      <geometry>
        <mesh filename="./meshes/arm/v10/visual/link4.stl" scale="0.001 0.001 0.001"/>
      </geometry>
      <material name="gray"/>
    </visual>
    <collision name="openarm_right_link4_collision">
      <origin rpy="0.0 0.0 0.0" xyz="0.0 -0.0315 -0.3425"/>
      <geometry>
        
        
      </geometry>
    </collision>
    <inertial>
      <origin rpy="0.0 0.0 0.0" xyz="-0.0029006831074562967 -0.03030575826634669 0.06339637422196209"/>
      <mass value="1.3699337287025453"/>
      <inertia ixx="0.001577" ixy="-5e-06" ixz="-7.5e-05" iyy="0.001346" iyz="0.000108" izz="0.001104"/>
    </inertial>
  </link>
  <joint name="R_J4" type="revolute">
    <origin rpy="0 0 0" xyz="-0.0 0.0315 0.15375"/>
    <parent link="openarm_right_link3"/>
    <child link="openarm_right_link4"/>
    <axis xyz="0 1 0"/>
    <limit effort="28" lower="0.0" upper="2.443461" velocity="8"/>
  </joint>
  <link name="openarm_right_link5">
    <visual name="openarm_right_link5_visual">
      <origin rpy="0.0 0.0 0.0" xyz="-0.0 -0.0 -0.438"/>
      <geometry>
        <mesh filename="./meshes/arm/v10/visual/link5.stl" scale="0.001 0.001 0.001"/>
      </geometry>
      <material name="dark_gray"/>
    </visual>
    <collision name="openarm_right_link5_collision">
      <origin rpy="0.0 0.0 0.0" xyz="-0.0 -0.0 -0.438"/>
      <geometry>
        
        
      </geometry>
    </collision>
    <inertial>
      <origin rpy="0.0 0.0 0.0" xyz="-0.003049665024221911 0.0008866902457326625 0.043079803024980934"/>
      <mass value="0.5506588026168502"/>
      <inertia ixx="0.000423" ixy="-8e-06" ixz="6e-06" iyy="0.000445" iyz="-6e-06" izz="0.000324"/>
    </inertial>
  </link>
  <joint name="R_J5" type="revolute">
    <origin rpy="0 0 0" xyz="0.0 -0.0315 0.0955"/>
    <parent link="openarm_right_link4"/>
    <child link="openarm_right_link5"/>
    <axis xyz="0 0 1"/>
    <limit effort="10" lower="-1.570796" upper="1.570796" velocity="30"/>
  </joint>
  <link name="openarm_right_link6">
    <visual name="openarm_right_link6_visual">
      <origin rpy="0.0 0.0 0.0" xyz="-0.0375 -0.0 -0.5585"/>
      <geometry>
        <mesh filename="./meshes/arm/v10/visual/link6.stl" scale="0.001 0.001 0.001"/>
      </geometry>
      <material name="light_black"/>
    </visual>
    <collision name="openarm_right_link6_collision">
      <origin rpy="0.0 0.0 0.0" xyz="-0.0375 -0.0 -0.5585"/>
      <geometry>
        
        
      </geometry>
    </collision>
    <inertial>
      <origin rpy="0.0 0.0 0.0" xyz="-0.037136587005447405 0.00033230528343419053 -9.498374522309838e-05"/>
      <mass value="0.3540202773187987"/>
      <inertia ixx="0.000143" ixy="4e-06" ixz="0.0" iyy="0.000157" iyz="1e-06" izz="0.000159"/>
    </inertial>
  </link>
  <joint name="R_J6" type="revolute">
    <origin rpy="0 0 0" xyz="0.0375 0.0 0.1205"/>
    <parent link="openarm_right_link5"/>
    <child link="openarm_right_link6"/>
    <axis xyz="1 0 0"/>
    <limit effort="10" lower="-0.785398" upper="0.785398" velocity="30"/>
  </joint>
  <link name="openarm_right_link7">
    <visual name="openarm_right_link7_visual">
      <origin rpy="0.0 0.0 0.0" xyz="0.0 -0.0 -0.5585"/>
      <geometry>
        <mesh filename="./meshes/arm/v10/visual/link7.stl" scale="0.001 0.001 0.001"/>
      </geometry>
      <material name="gray"/>
    </visual>
    <collision name="openarm_right_link7_collision">
      <origin rpy="0.0 0.0 0.0" xyz="0.0 -0.0 -0.5585"/>
      <geometry>
        
        
      </geometry>
    </collision>
    <inertial>
      <origin rpy="0.0 0.0 0.0" xyz="6.875510271106056e-05 -0.01766175250761268 0.06651945409987448"/>
      <mass value="0.5499771327380578"/>
      <inertia ixx="0.000639" ixy="0.0" ixz="-0.0" iyy="0.000497" iyz="8.9e-05" izz="0.000342"/>
    </inertial>
  </link>
  <joint name="R_J7" type="revolute">
    <origin rpy="0 0 0" xyz="-0.0375 0.0 0.0"/>
    <parent link="openarm_right_link6"/>
    <child link="openarm_right_link7"/>
    <axis xyz="0 1 0"/>
    <limit effort="10" lower="-1.570796" upper="1.570796" velocity="30"/>
  </joint>
  <link name="openarm_right_link8"/>
  <joint name="R_J8" type="fixed">
    <origin rpy="0 0 0" xyz="1e-06 0.0205 0.0"/>
    <parent link="openarm_right_link7"/>
    <child link="openarm_right_link8"/>
  </joint>
  <link name="openarm_left_hand">
    <visual name="openarm_left_hand_visual">
      <origin rpy="0.0 0.0 0.0" xyz="0.0 0.005 -0.6585"/>
      <geometry>
        <mesh filename="./meshes/ee/openarm_hand/visual/hand.stl" scale="0.001 0.001 0.001"/>
      </geometry>
      <material name="light_gray"/>
    </visual>
    <collision name="openarm_left_hand_collision">
      <origin rpy="0.0 0.0 0.0" xyz="0.0 0.005 -0.6585"/>
      <geometry>
        
      </geometry>
    </collision>
    <inertial>
      <origin rpy="0 0 0" xyz="0.0 0.002 0.01"/>
      <mass value="0.15"/>
      <inertia ixx="0.0001" ixy="0" ixz="0" iyy="0.00025" iyz="0" izz="0.00017"/>
    </inertial>
  </link>
  <!-- <link name="${ee_prefix}hand"/> -->
  <!-- <joint name="${ee_prefix}hand_joint" type="fixed"> -->
  <joint name="left_openarm_hand_joint" type="fixed">
    <parent link="openarm_left_link8"/>
    <child link="openarm_left_hand"/>
    <origin rpy="0 0 0" xyz="0 -0.025 0.1001"/>
  </joint>
  <!-- Define the hand_tcp frame -->
  <link name="openarm_left_hand_tcp"/>
  <joint name="openarm_left_hand_tcp_joint" type="fixed">
    <origin rpy="0 0 0" xyz="0 -0.0 0.08"/>
    <parent link="openarm_left_hand"/>
    <child link="openarm_left_hand_tcp"/>
  </joint>
  <link name="openarm_left_left_finger">
    <visual name="openarm_left_left_finger_visual">
      <origin rpy="0.0 0.0 0.0" xyz="0.0 -0.05 -0.673001"/>
      <geometry>
        <mesh filename="./meshes/ee/openarm_hand/visual/finger.stl" scale="0.001 0.001 0.001"/>
      </geometry>
      <material name="light_black"/>
    </visual>
    <collision name="openarm_left_left_finger_collision">
      <origin rpy="0.0 0.0 0.0" xyz="0.0 -0.05 -0.673001"/>
      <geometry>
        
      </geometry>
    </collision>
    <inertial>
      <origin rpy="0 0 0" xyz="0.0064528 0.01702 0.0219685"/>
      <mass value="0.03602545343277134"/>
      <inertia ixx="2.3749999999999997e-06" ixy="0" ixz="0" iyy="2.3749999999999997e-06" iyz="0" izz="7.5e-07"/>
    </inertial>
  </link>
  <link name="openarm_left_right_finger">
    <visual name="openarm_left_right_finger_visual">
      <origin rpy="0.0 0.0 0.0" xyz="0.0 0.05 -0.673001"/>
      <geometry>
        <mesh filename="./meshes/ee/openarm_hand/visual/finger.stl" scale="0.001 -0.001 0.001"/>
      </geometry>
      <material name="light_black"/>
    </visual>
    <collision name="openarm_left_right_finger_collision">
      <origin rpy="0.0 0.0 0.0" xyz="0.0 0.05 -0.673001"/>
      <geometry>
        
      </geometry>
    </collision>
    <inertial>
      <origin rpy="0 0 0" xyz="0.0064528 -0.01702 0.0219685"/>
      <mass value="0.03602545343277134"/>
      <inertia ixx="2.3749999999999997e-06" ixy="0" ixz="0" iyy="2.3749999999999997e-06" iyz="0" izz="7.5e-07"/>
    </inertial>
  </link>
  <joint name="L_EE" type="prismatic">
    <parent link="openarm_left_hand"/>
    <child link="openarm_left_right_finger"/>
    <origin rpy="0 0 0" xyz="0 0.00 0.015"/>
    <axis xyz="0 -1 0"/>
    <limit effort="333" lower="0.0" upper="0.044" velocity="10.0"/>
  </joint>
  <joint name="L_EE2" type="prismatic">
    <parent link="openarm_left_hand"/>
    <child link="openarm_left_left_finger"/>
    <origin rpy="0 0 0" xyz="0 0.012 0.015"/>
    <axis xyz="0 1 0"/>
    <limit effort="333" lower="0.0" upper="0.044" velocity="10.0"/>
    <mimic joint="L_EE"/>
  </joint>
  <link name="openarm_right_hand">
    <visual name="openarm_right_hand_visual">
      <origin rpy="0.0 0.0 0.0" xyz="0.0 0.005 -0.6585"/>
      <geometry>
        <mesh filename="./meshes/ee/openarm_hand/visual/hand.stl" scale="0.001 0.001 0.001"/>
      </geometry>
      <material name="light_gray"/>
    </visual>
    <collision name="openarm_right_hand_collision">
      <origin rpy="0.0 0.0 0.0" xyz="0.0 0.005 -0.6585"/>
      <geometry>
        
      </geometry>
    </collision>
    <inertial>
      <origin rpy="0 0 0" xyz="0.0 0.002 0.01"/>
      <mass value="0.15"/>
      <inertia ixx="0.0001" ixy="0" ixz="0" iyy="0.00025" iyz="0" izz="0.00017"/>
    </inertial>
  </link>
  <!-- <link name="${ee_prefix}hand"/> -->
  <!-- <joint name="${ee_prefix}hand_joint" type="fixed"> -->
  <joint name="right_openarm_hand_joint" type="fixed">
    <parent link="openarm_right_link8"/>
    <child link="openarm_right_hand"/>
    <origin rpy="0 0 0" xyz="0 -0.025 0.1001"/>
  </joint>
  <!-- Define the hand_tcp frame -->
  <link name="openarm_right_hand_tcp"/>
  <joint name="openarm_right_hand_tcp_joint" type="fixed">
    <origin rpy="0 0 0" xyz="0 -0.0 0.08"/>
    <parent link="openarm_right_hand"/>
    <child link="openarm_right_hand_tcp"/>
  </joint>
  <link name="openarm_right_left_finger">
    <visual name="openarm_right_left_finger_visual">
      <origin rpy="0.0 0.0 0.0" xyz="0.0 -0.05 -0.673001"/>
      <geometry>
        <mesh filename="./meshes/ee/openarm_hand/visual/finger.stl" scale="0.001 0.001 0.001"/>
      </geometry>
      <material name="light_black"/>
    </visual>
    <collision name="openarm_right_left_finger_collision">
      <origin rpy="0.0 0.0 0.0" xyz="0.0 -0.05 -0.673001"/>
      <geometry>
        
      </geometry>
    </collision>
    <inertial>
      <origin rpy="0 0 0" xyz="0.0064528 0.01702 0.0219685"/>
      <mass value="0.03602545343277134"/>
      <inertia ixx="2.3749999999999997e-06" ixy="0" ixz="0" iyy="2.3749999999999997e-06" iyz="0" izz="7.5e-07"/>
    </inertial>
  </link>
  <link name="openarm_right_right_finger">
    <visual name="openarm_right_right_finger_visual">
      <origin rpy="0.0 0.0 0.0" xyz="0.0 0.05 -0.673001"/>
      <geometry>
        <mesh filename="./meshes/ee/openarm_hand/visual/finger.stl" scale="0.001 -0.001 0.001"/>
      </geometry>
      <material name="light_black"/>
    </visual>
    <collision name="openarm_right_right_finger_collision">
      <origin rpy="0.0 0.0 0.0" xyz="0.0 0.05 -0.673001"/>
      <geometry>
        
      </geometry>
    </collision>
    <inertial>
      <origin rpy="0 0 0" xyz="0.0064528 -0.01702 0.0219685"/>
      <mass value="0.03602545343277134"/>
      <inertia ixx="2.3749999999999997e-06" ixy="0" ixz="0" iyy="2.3749999999999997e-06" iyz="0" izz="7.5e-07"/>
    </inertial>
  </link>
  <joint name="R_EE" type="prismatic">
    <parent link="openarm_right_hand"/>
    <child link="openarm_right_right_finger"/>
    <origin rpy="0 0 0" xyz="0 0.00 0.015"/>
    <axis xyz="0 -1 0"/>
    <limit effort="333" lower="0.0" upper="0.044" velocity="10.0"/>
  </joint>
  <joint name="R_EE2" type="prismatic">
    <parent link="openarm_right_hand"/>
    <child link="openarm_right_left_finger"/>
    <origin rpy="0 0 0" xyz="0 0.012 0.015"/>
    <axis xyz="0 1 0"/>
    <limit effort="333" lower="0.0" upper="0.044" velocity="10.0"/>
    <mimic joint="R_EE"/>
  </joint>
  <!-- <xacro:if value="${gazebo}">
        <xacro:if value="${parent != ''}">
            <xacro:if value="${parent == 'world'}">
            <link name="${parent}" />
            </xacro:if>
            <joint name="${parent}_joint" type="fixed">
            <origin xyz="${xyz}" rpy="${rpy}" />
            <parent link="${parent}" />
            <child  link="${arm_type}_link0" />
            </joint>
        </xacro:if> -->
  <!-- <xacro:gazebo-joint joint="${arm_type}_joint1" transmission="hardware_interface/PositionJointInterface" />
        <xacro:gazebo-joint joint="${arm_type}_joint2" transmission="hardware_interface/PositionJointInterface" />
        <xacro:gazebo-joint joint="${arm_type}_joint3" transmission="hardware_interface/PositionJointInterface" />
        <xacro:gazebo-joint joint="${arm_type}_joint4" transmission="hardware_interface/PositionJointInterface" />
        <xacro:gazebo-joint joint="${arm_type}_joint5" transmission="hardware_interface/PositionJointInterface" />
        <xacro:gazebo-joint joint="${arm_type}_joint6" transmission="hardware_interface/PositionJointInterface" />
        <xacro:gazebo-joint joint="${arm_type}_joint7" transmission="hardware_interface/PositionJointInterface" />

        <xacro:gazebo-joint joint="${arm_type}_joint1" transmission="hardware_interface/VelocityJointInterface" />
        <xacro:gazebo-joint joint="${arm_type}_joint2" transmission="hardware_interface/VelocityJointInterface" />
        <xacro:gazebo-joint joint="${arm_type}_joint3" transmission="hardware_interface/VelocityJointInterface" />
        <xacro:gazebo-joint joint="${arm_type}_joint4" transmission="hardware_interface/VelocityJointInterface" />
        <xacro:gazebo-joint joint="${arm_type}_joint5" transmission="hardware_interface/VelocityJointInterface" />
        <xacro:gazebo-joint joint="${arm_type}_joint6" transmission="hardware_interface/VelocityJointInterface" />
        <xacro:gazebo-joint joint="${arm_type}_joint7" transmission="hardware_interface/VelocityJointInterface" />

        <xacro:gazebo-joint joint="${arm_type}_joint1" transmission="hardware_interface/EffortJointInterface" />
        <xacro:gazebo-joint joint="${arm_type}_joint2" transmission="hardware_interface/EffortJointInterface" />
        <xacro:gazebo-joint joint="${arm_type}_joint3" transmission="hardware_interface/EffortJointInterface" />
        <xacro:gazebo-joint joint="${arm_type}_joint4" transmission="hardware_interface/EffortJointInterface" />
        <xacro:gazebo-joint joint="${arm_type}_joint5" transmission="hardware_interface/EffortJointInterface" />
        <xacro:gazebo-joint joint="${arm_type}_joint6" transmission="hardware_interface/EffortJointInterface" />
        <xacro:gazebo-joint joint="${arm_type}_joint7" transmission="hardware_interface/EffortJointInterface" />  -->
  <!-- <xacro:transmission-openarm-state arm_type="${arm_type}" />
        <xacro:transmission-openarm-model arm_type="${arm_type}"
            root="${arm_type}_joint1"
            tip="${arm_type}_joint8"
        /> -->
  <!-- <xacro:if value="${ee_type == 'openarm_hand'}">
            <xacro:gazebo-joint joint="${arm_type}_finger_joint1" transmission="hardware_interface/EffortJointInterface" />
            <xacro:gazebo-joint joint="${arm_type}_finger_joint2" transmission="hardware_interface/EffortJointInterface" />
            <xacro:gazebo-friction link="${arm_type}_leftfinger" mu="1.13" />
            <xacro:gazebo-friction link="${arm_type}_rightfinger" mu="1.13" />
        </xacro:if>
        </xacro:if> -->
</robot>
